Workbook

Sheet 关系明细
A1: 工段 (Area) | B1: 关系大类 (Category) | C1: 起始对象类型 (Subject Type) | D1: 起始对象语义名称 (Subject Entity) | E1: 关系谓词 / 边类型 (Predicate) | F1: 目标对象类型 (Object Type) | G1: 目标对象语义名称 (Object Entity) | H1: 工艺机理与业务因果说明 (Domain Description) | I1: 子场景 | J1: 权重 | K1: 工段编号 | L1: 关系ID | M1: 主体URI | N1: 谓词URI | O1: 客体URI | P1: 关联DCS位号 | Q1: 依据来源 | R1: 置信度 | S1: 流程画面 | T1: 变更标记
A2: 提取·RSE300一/二萃 | B2: 工段衔接 | C2: 生产工段 | D2: 提取·RSE300一/二萃 | E2: 串联下游 | F2: 生产工段 | G2: 提取·RSE200三萃及溶媒周转 | H2: 衔接物料：二级废酸水。RSE300重相（二级废酸水）送RSE200三萃 | I2: 工段衔接 | J2: 1 | K2: S01 | L2: R0001 | M2: :Area_S01_Extraction_RSE300 | N2: :connectedToNext | O2: :Area_S02_Extraction_RSE200 | Q2: 流程图画面 | R2: 高 | T2: v2新增
A3: 提取·RSE300一/二萃 | B3: 工段衔接 | C3: 生产工段 | D3: 提取·RSE300一/二萃 | E3: 串联下游 | F3: 生产工段 | G3: BA水洗 | H3: 衔接物料：一次BA。富青霉素一次BA经一次BA缓冲罐V2136送水洗离心机 | I3: 工段衔接 | J3: 1 | K3: S01 | L3: R0002 | M3: :Area_S01_Extraction_RSE300 | N3: :connectedToNext | O3: :Area_S05_BAWashing | Q3: 流程图画面 | R3: 高 | T3: v2新增
A4: 提取·RSE300一/二萃 | B4: 结构关系 | C4: 生产工段 | D4: 提取·RSE300一/二萃 | E4: 包含设备 | F4: 生产设备 | G4: 发酵滤液储罐组 | H4: 提取·RSE300一/二萃包含储罐“发酵滤液储罐组” | I4: 常态 | J4: 1 | K4: S01 | L4: R0003 | M4: :Area_S01_Extraction_RSE300 | N4: :hasEquipment | O4: :FiltrateTankGroup | Q4: 流程图画面/DCS点表 | R4: 高 | S4: 提取RSE300 | T4: v2新增
A5: 提取·RSE300一/二萃 | B5: 结构关系 | C5: 生产设备 | D5: 发酵滤液储罐组 | E5: 包含实例 | F5: 设备实例 | G5: 滤液储罐T2101(滤液罐A) | H5: 发酵滤液储罐组的并联/编号实例 | I5: 常态 | J5: 1 | K5: S01 | L5: R0004 | M5: :FiltrateTankGroup | N5: :hasMember | O5: :FiltrateTankGroup_M01 | Q5: 流程图画面/DCS点表 | R5: 高 | S5: 提取RSE300 | T5: v2新增
A6: 提取·RSE300一/二萃 | B6: 结构关系 | C6: 生产设备 | D6: 发酵滤液储罐组 | E6: 包含实例 | F6: 设备实例 | G6: 滤液罐B | H6: 发酵滤液储罐组的并联/编号实例 | I6: 常态 | J6: 1 | K6: S01 | L6: R0005 | M6: :FiltrateTankGroup | N6: :hasMember | O6: :FiltrateTankGroup_M02 | Q6: 流程图画面/DCS点表 | R6: 高 | S6: 提取RSE300 | T6: v2新增
A7: 提取·RSE300一/二萃 | B7: 结构关系 | C7: 生产设备 | D7: 发酵滤液储罐组 | E7: 具有部件 | F7: 设备部件 | G7: 发酵滤液储罐组·液位计 | H7: 发酵滤液储罐组配置液位计 | I7: 常态 | J7: 1 | K7: S01 | L7: R0006 | M7: :FiltrateTankGroup | N7: :hasPart | O7: :FiltrateTankGroup_P01 | Q7: 流程图画面 | R7: 中 | S7: 提取RSE300 | T7: v2新增
A8: 提取·RSE300一/二萃 | B8: 结构关系 | C8: 生产设备 | D8: 发酵滤液储罐组 | E8: 具有部件 | F8: 设备部件 | G8: 发酵滤液储罐组·温度计 | H8: 发酵滤液储罐组配置温度计 | I8: 常态 | J8: 1 | K8: S01 | L8: R0007 | M8: :FiltrateTankGroup | N8: :hasPart | O8: :FiltrateTankGroup_P02 | Q8: 流程图画面 | R8: 中 | S8: 提取RSE300 | T8: v2新增
A9: 提取·RSE300一/二萃 | B9: 结构关系 | C9: 生产工段 | D9: 提取·RSE300一/二萃 | E9: 包含设备 | F9: 生产设备 | G9: 滤液泵组 | H9: 提取·RSE300一/二萃包含泵“滤液泵组” | I9: 常态 | J9: 1 | K9: S01 | L9: R0008 | M9: :Area_S01_Extraction_RSE300 | N9: :hasEquipment | O9: :FiltratePumpGroup | Q9: 流程图画面/DCS点表 | R9: 高 | S9: 提取RSE300 | T9: v2新增
A10: 提取·RSE300一/二萃 | B10: 结构关系 | C10: 生产设备 | D10: 滤液泵组 | E10: 包含实例 | F10: 设备实例 | G10: 滤液泵A | H10: 滤液泵组的并联/编号实例 | I10: 常态 | J10: 1 | K10: S01 | L10: R0009 | M10: :FiltratePumpGroup | N10: :hasMember | O10: :FiltratePumpGroup_M01 | Q10: 流程图画面/DCS点表 | R10: 高 | S10: 提取RSE300 | T10: v2新增
A11: 提取·RSE300一/二萃 | B11: 结构关系 | C11: 生产设备 | D11: 滤液泵组 | E11: 包含实例 | F11: 设备实例 | G11: 滤液泵B | H11: 滤液泵组的并联/编号实例 | I11: 常态 | J11: 1 | K11: S01 | L11: R0010 | M11: :FiltratePumpGroup | N11: :hasMember | O11: :FiltratePumpGroup_M02 | Q11: 流程图画面/DCS点表 | R11: 高 | S11: 提取RSE300 | T11: v2新增
A12: 提取·RSE300一/二萃 | B12: 结构关系 | C12: 生产设备 | D12: 滤液泵组 | E12: 包含实例 | F12: 设备实例 | G12: 滤液泵C | H12: 滤液泵组的并联/编号实例 | I12: 常态 | J12: 1 | K12: S01 | L12: R0011 | M12: :FiltratePumpGroup | N12: :hasMember | O12: :FiltratePumpGroup_M03 | Q12: 流程图画面/DCS点表 | R12: 高 | S12: 提取RSE300 | T12: v2新增
A13: 提取·RSE300一/二萃 | B13: 结构关系 | C13: 生产设备 | D13: 滤液泵组 | E13: 包含实例 | F13: 设备实例 | G13: 滤液泵D | H13: 滤液泵组的并联/编号实例 | I13: 常态 | J13: 1 | K13: S01 | L13: R0012 | M13: :FiltratePumpGroup | N13: :hasMember | O13: :FiltratePumpGroup_M04 | Q13: 流程图画面/DCS点表 | R13: 高 | S13: 提取RSE300 | T13: v2新增
A14: 提取·RSE300一/二萃 | B14: 结构关系 | C14: 生产设备 | D14: 滤液泵组 | E14: 包含实例 | F14: 设备实例 | G14: 滤液泵E | H14: 滤液泵组的并联/编号实例 | I14: 常态 | J14: 1 | K14: S01 | L14: R0013 | M14: :FiltratePumpGroup | N14: :hasMember | O14: :FiltratePumpGroup_M05 | Q14: 流程图画面/DCS点表 | R14: 高 | S14: 提取RSE300 | T14: v2新增
A15: 提取·RSE300一/二萃 | B15: 结构关系 | C15: 生产设备 | D15: 滤液泵组 | E15: 包含实例 | F15: 设备实例 | G15: 滤液泵F | H15: 滤液泵组的并联/编号实例 | I15: 常态 | J15: 1 | K15: S01 | L15: R0014 | M15: :FiltratePumpGroup | N15: :hasMember | O15: :FiltratePumpGroup_M06 | Q15: 流程图画面/DCS点表 | R15: 高 | S15: 提取RSE300 | T15: v2新增
... A39: 提取·RSE300一/二萃 | B39: 结构关系 | C39: 生产设备 | D39: 三级废酸水罐/废酸水中和罐V2124 | E39: 具有部件 | F39: 设备部件 | G39: 三级废酸水罐/废酸水中和罐V2124·液碱调节阀 | H39: 三级废酸水罐/废酸水中和罐V2124配置液碱调节阀 | I39: 常态 | J39: 1 | K39: S01 | L39: R0038 | M39: :WasteAcidNeutralizerV2124 | N39: :hasPart | O39: :WasteAcidNeutralizerV2124_P02 | Q39: 流程图画面 | R39: 中 | S39: 提取RSE300 | T39: v2新增
A40: 提取·RSE300一/二萃 | B40: 结构关系 | C40: 生产设备 | D40: 发酵滤液储罐组 | E40: 具有属性 | F40: 工艺属性 | G40: 滤液罐液位 | H40: 滤液储罐T2101液位 | I40: 常态 | J40: 1 | K40: S01 | L40: R0039 | M40: :FiltrateTankGroup | N40: :hasAttribute | O40: :Attr_001 | P40: LT_1102 | Q40: DCS点表 | R40: 高 | S40: 提取RSE300 | T40: v2新增
A41: 提取·RSE300一/二萃 | B41: 结构关系 | C41: 生产设备 | D41: 发酵滤液储罐组 | E41: 具有属性 | F41: 工艺属性 | G41: 滤液温度 | H41: 滤液储罐温度，影响青霉素稳定性 | I41: 常态 | J41: 1 | K41: S01 | L41: R0040 | M41: :FiltrateTankGroup | N41: :hasAttribute | O41: :Attr_002 | P41: TI_1101 | Q41: DCS点表 | R41: 高 | S41: 提取RSE300 | T41: v2新增
A42: 提取·RSE300一/二萃 | B42: 结构关系 | C42: 生产设备 | D42: 发酵滤液储罐组 | E42: 具有属性 | F42: 工艺属性 | G42: 滤液罐进料流量 | H42: 发酵滤液来料流量 | I42: 常态 | J42: 1 | K42: S01 | L42: R0041 | M42: :FiltrateTankGroup | N42: :hasAttribute | O42: :Attr_003 | P42: FT_1103、FT_1004 | Q42: DCS点表 | R42: 高 | S42: 提取RSE300 | T42: v2新增
A43: 提取·RSE300一/二萃 | B43: 结构关系 | C43: 生产设备 | D43: RSE300提取离心机组 | E43: 具有属性 | F43: 工艺属性 | G43: 滤液进料流量 | H43: RSE300各组(1-2/3-4/5-6)滤液进料 | I43: 常态 | J43: 1 | K43: S01 | L43: R0042 | M43: :RSE300CentrifugeGroup | N43: :hasAttribute | O43: :Attr_004 | P43: FT_1104C、FT_1104D、FT_1104E | Q43: DCS点表 | R43: 高 | S43: 提取RSE300 | T43: v2新增
A44: 提取·RSE300一/二萃 | B44: 结构关系 | C44: 生产设备 | D44: RSE300提取离心机组 | E44: 具有属性 | F44: 工艺属性 | G44: BA进料流量 | H44: 丁酯/BA进料 | I44: 常态 | J44: 1 | K44: S01 | L44: R0043 | M44: :RSE300CentrifugeGroup | N44: :hasAttribute | O44: :Attr_005 | P44: FT_1105C、FT_1105D、FT_1105E | Q44: DCS点表 | R44: 高 | S44: 提取RSE300 | T44: v2新增
A45: 提取·RSE300一/二萃 | B45: 结构关系 | C45: 生产设备 | D45: RSE300提取离心机组 | E45: 具有属性 | F45: 工艺属性 | G45: 破乳剂进料流量 | H45: 破乳剂注入量 | I45: 常态 | J45: 1 | K45: S01 | L45: R0044 | M45: :RSE300CentrifugeGroup | N45: :hasAttribute | O45: :Attr_006 | P45: FT_1101C、FT_1101D、FT_1101E | Q45: DCS点表 | R45: 高 | S45: 提取RSE300 | T45: v2新增
A46: 提取·RSE300一/二萃 | B46: 结构关系 | C46: 生产设备 | D46: RSE300提取离心机组 | E46: 具有属性 | F46: 工艺属性 | G46: 一阶段酸化pH | H46: 一阶段萃取pH | I46: 常态 | J46: 1 | K46: S01 | L46: R0045 | M46: :RSE300CentrifugeGroup | N46: :hasAttribute | O46: :Attr_007 | P46: AT_1105、AT_1107、AT_1109 | Q46: DCS点表 | R46: 高 | S46: 提取RSE300 | T46: v2新增
A47: 提取·RSE300一/二萃 | B47: 结构关系 | C47: 生产设备 | D47: RSE300提取离心机组 | E47: 具有属性 | F47: 工艺属性 | G47: 二阶段酸化pH | H47: 二阶段萃取pH | I47: 常态 | J47: 1 | K47: S01 | L47: R0046 | M47: :RSE300CentrifugeGroup | N47: :hasAttribute | O47: :Attr_008 | P47: AT_1106、AT_1108、AT_1110 | Q47: DCS点表 | R47: 高 | S47: 提取RSE300 | T47: v2新增
A48: 提取·RSE300一/二萃 | B48: 结构关系 | C48: 生产设备 | D48: RSE300提取离心机组 | E48: 具有属性 | F48: 工艺属性 | G48: 重相出口压力 | H48: 重相向心泵背压 | I48: 常态 | J48: 1 | K48: S01 | L48: R0047 | M48: :RSE300CentrifugeGroup | N48: :hasAttribute | O48: :Attr_009 | P48: PT_1001A、PT_1001B、PT_1001C、PT_1001D、PT_1001E | Q48: DCS点表 | R48: 高 | S48: 提取RSE300 | T48: v2新增
A49: 提取·RSE300一/二萃 | B49: 结构关系 | C49: 生产设备 | D49: RSE300提取离心机组 | E49: 具有属性 | F49: 工艺属性 | G49: 轻相出口压力 | H49: 轻相向心泵背压 | I49: 常态 | J49: 1 | K49: S01 | L49: R0048 | M49: :RSE300CentrifugeGroup | N49: :hasAttribute | O49: :Attr_010 | P49: PT_1002A、PT_1002B、PT_1002C、PT_1002D、PT_1002E | Q49: DCS点表 | R49: 高 | S49: 提取RSE300 | T49: v2新增
A50: 提取·RSE300一/二萃 | B50: 结构关系 | C50: 生产设备 | D50: RSE300提取离心机组 | E50: 具有属性 | F50: 工艺属性 | G50: 主电机电流 | H50: 负荷/排渣状态指示 | I50: 常态 | J50: 1 | K50: S01 | L50: R0049 | M50: :RSE300CentrifugeGroup | N50: :hasAttribute | O50: :Attr_011 | P50: II_10CQA、II_10CQB、II_10CQC、II_10CQD、II_10CQE、II_10CQF | Q50: DCS点表 | R50: 高 | S50: 提取RSE300 | T50: v2新增
A51: 提取·RSE300一/二萃 | B51: 结构关系 | C51: 生产设备 | D51: 稀硫酸在线混合器M2123 | E51: 具有属性 | F51: 工艺属性 | G51: 稀硫酸注入流量 | H51: 各混合器稀硫酸流量 | I51: 常态 | J51: 1 | K51: S01 | L51: R0050 | M51: :AcidMixerM2123 | N51: :hasAttribute | O51: :Attr_012 | P51: FT_1106A、FT_1106B、FT_1106C、FT_1106D、FT_1106E | Q51: DCS点表 | R51: 高 | S51: 提取RSE300 | T51: v2新增
... A54: 提取·RSE300一/二萃 | B54: 结构关系 | C54: 生产设备 | D54: 三级废酸水罐/废酸水中和罐V2124 | E54: 具有属性 | F54: 工艺属性 | G54: 废酸水外送流量 | H54: 去回收流量/密度 | I54: 常态 | J54: 1 | K54: S01 | L54: R0053 | M54: :WasteAcidNeutralizerV2124 | N54: :hasAttribute | O54: :Attr_015 | P54: FT_2001、DI_2001 | Q54: DCS点表 | R54: 高 | S54: 提取RSE300 | T54: v2新增
A55: 提取·RSE300一/二萃 | B55: 结构关系 | C55: 生产设备 | D55: RSE300提取离心机组 | E55: 具有属性 | F55: 工艺属性 | G55: 萃取分配系数(青霉素G) | H55: 酸性下青霉素G游离酸进入BA的分配比 | I55: 常态 | J55: 1 | K55: S01 | L55: R0054 | M55: :RSE300CentrifugeGroup | N55: :hasAttribute | O55: :Attr_248 | Q55: 工艺机理 | R55: 中 | S55: 提取RSE300 | T55: v2新增
A56: 提取·RSE300一/二萃 | B56: 结构关系 | C56: 生产设备 | D56: RSE300提取离心机组 | E56: 具有属性 | F56: 工艺属性 | G56: 青霉素酸降解速率 | H56: 低pH/高温下青霉素G酸不稳定降解 | I56: 常态 | J56: 1 | K56: S01 | L56: R0055 | M56: :RSE300CentrifugeGroup | N56: :hasAttribute | O56: :Attr_249 | Q56: 工艺机理 | R56: 中 | S56: 提取RSE300 | T56: v2新增
A57: 提取·RSE300一/二萃 | B57: 结构关系 | C57: 生产设备 | D57: RSE300提取离心机组 | E57: 具有属性 | F57: 工艺属性 | G57: 相界面乳化层厚度 | H57: 蛋白质等表面活性物造成乳化 | I57: 常态 | J57: 1 | K57: S01 | L57: R0056 | M57: :RSE300CentrifugeGroup | N57: :hasAttribute | O57: :Attr_250 | Q57: 工艺机理 | R57: 中 | S57: 提取RSE300 | T57: v2新增
A58: 提取·RSE300一/二萃 | B58: 结构关系 | C58: 生产设备 | D58: 三级废酸水罐/废酸水中和罐V2124 | E58: 具有属性 | F58: 质量指标 | G58: 提取废酸水残效 | H58: 废酸水中残留青霉素，提取损失 | I58: 常态 | J58: 1 | K58: S01 | L58: R0057 | M58: :WasteAcidNeutralizerV2124 | N58: :hasAttribute | O58: :QKPI_253 | Q58: 工艺机理 | R58: 中 | S58: 提取RSE300 | T58: v2新增
A59: 提取·RSE300一/二萃 | B59: 结构关系 | C59: 物料流股 | D59: 青霉素G发酵滤液 | E59: 具有属性 | F59: 工艺属性 | G59: 滤液温度 | H59: 青霉素G发酵滤液的滤液温度（流股属性，测点位于管线/承载设备） | I59: 常态 | J59: 1 | K59: S01 | L59: R0058 | M59: :MS_Filtrate | N59: :hasAttribute | O59: :Attr_002 | P59: TI_1101 | Q59: DCS点表 | R59: 高 | S59: 提取RSE300 | T59: v2新增
A60: 提取·RSE300一/二萃 | B60: 结构关系 | C60: 物料流股 | D60: 一次BA | E60: 具有属性 | F60: 质量指标 | G60: 一次BA青霉素效价 | H60: 一次BA的一次BA青霉素效价（流股属性，测点位于管线/承载设备） | I60: 常态 | J60: 1 | K60: S01 | L60: R0059 | M60: :MS_PrimaryBA | N60: :hasAttribute | O60: :QKPI_252 | Q60: 工艺机理 | R60: 中 | S60: 提取RSE300 | T60: v2新增
A61: 提取·RSE300一/二萃 | B61: 测点绑定关系 | C61: 工艺属性 | D61: 滤液罐液位 | E61: 绑定测点 | F61: DCS测点 | G61: LT_1102 | H61: DCS原点描述：滤液储罐T2101液位 | I61: 常态 | J61: 1 | K61: S01 | L61: R0060 | M61: :Attr_001 | N61: :boundToTag | O61: :LT_1102 | P61: LT_1102 | Q61: DCS点表 | R61: 高 | S61: 提取RSE300 | T61: v2新增
A62: 提取·RSE300一/二萃 | B62: 测点绑定关系 | C62: 工艺属性 | D62: 滤液温度 | E62: 绑定测点 | F62: DCS测点 | G62: TI_1101 | H62: DCS原点描述：滤液储罐T2101温度 | I62: 常态 | J62: 1 | K62: S01 | L62: R0061 | M62: :Attr_002 | N62: :boundToTag | O62: :TI_1101 | P62: TI_1101 | Q62: DCS点表 | R62: 高 | S62: 提取RSE300 | T62: v2新增
A63: 提取·RSE300一/二萃 | B63: 测点绑定关系 | C63: 工艺属性 | D63: 滤液罐进料流量 | E63: 绑定测点 | F63: DCS测点 | G63: FT_1103 | H63: DCS原点描述：滤液储罐T2101进料流量 | I63: 常态 | J63: 1 | K63: S01 | L63: R0062 | M63: :Attr_003 | N63: :boundToTag | O63: :FT_1103 | P63: FT_1103 | Q63: DCS点表 | R63: 高 | S63: 提取RSE300 | T63: v2新增
A64: 提取·RSE300一/二萃 | B64: 测点绑定关系 | C64: 工艺属性 | D64: 滤液罐进料流量 | E64: 绑定测点 | F64: DCS测点 | G64: FT_1004 | H64: DCS原点描述：滤液罐进口流量 | I64: 常态 | J64: 1 | K64: S01 | L64: R0063 | M64: :Attr_003 | N64: :boundToTag | O64: :FT_1004 | P64: FT_1004 | Q64: DCS点表 | R64: 高 | S64: 提取RSE300 | T64: v2新增
A65: 提取·RSE300一/二萃 | B65: 测点绑定关系 | C65: 工艺属性 | D65: 滤液进料流量 | E65: 绑定测点 | F65: DCS测点 | G65: FT_1104C | H65: DCS原点描述：离心机300（1—2）滤液进料流量 | I65: 常态 | J65: 1 | K65: S01 | L65: R0064 | M65: :Attr_004 | N65: :boundToTag | O65: :FT_1104C | P65: FT_1104C | Q65: DCS点表 | R65: 高 | S65: 提取RSE300 | T65: v2新增
...

Sheet 说明
A1: 6-APA 工业关系库 v2（全流程展开）
A3: 覆盖范围 | B3: v1仅覆盖“水解+萃取”两个工段（71条）。v2依据16张DCS流程画面+10,680个DCS点，展开为24个工段（含提取、稀硫酸/破乳剂配制、水洗、脱色、抽提、钾盐副线、薄膜、水解配制、水解、萃取/反萃、批次结晶、连续结晶、结晶辅料、干燥、母液/溶媒/苯乙酸/废水回收、公用、尾气）。
A4: 关系明细 | B4: 保留v1的前10列结构不变；新增K–T列：工段编号、关系ID、主体/谓词/客体URI、关联DCS位号、依据来源、置信度、流程画面、变更标记（原有保留/原有修订/v2新增）。
A5: 关系类型 | B5: 新增“工段衔接”“测点绑定关系”“报警联锁关系”三类及 hasEquipment / hasMember / boundToTag / injectedInto / dosedInto / recyclesTo / separatesInto / suppliesUtility / triggersAlarm 等谓词，均为v1谓词的子属性或补充，v1查询可兼容。
A6: 置信度 | B6: 高=流程画面或点表直接可见；中=画面+点表联合推断或公认工艺机理；低=工艺推断，需现场确认（如RSE200轻相逆流回RSE300、反萃重相去苯乙酸塔的中间步骤）。
A7: v1修订 | B7: v1萃取工段把“水洗碟片离心机组、稀硫酸、醋酸丁酯、破乳剂”当作萃取主体，与萃取画面（萃取离心机A–J、盐酸、混合溶媒）不符，已逐条修订并迁移，详见“v1→v2修订记录”；v1原表存档于“原关系明细(v1存档)”。
A8: 与点表联动 | B8: 实体名称与《6APA_DCS_完善版》“标准设备组/绑定本体属性”列一致；关联DCS位号均已校验在点表中存在（点表未收录的画面位号见DCS文件“画面补充测点”）。
A10: 统计项 | B10: 数值
A11: 关系总数 | B11: =COUNTA(关系明细!L2:L2253) -> 2252
A12: 其中v2新增 | B12: =COUNTIF(关系明细!T2:T2253,"v2新增") -> 2181
A13: 其中承接v1(保留+修订) | B13: =COUNTIF(关系明细!T2:T2253,"原有*") -> 71
A14: 高置信关系 | B14: =COUNTIF(关系明细!R2:R2253,"高") -> 1719
A15: 低置信关系(待确认) | B15: =COUNTIF(关系明细!R2:R2253,"低") -> 16
A16: 实体节点数 | B16: =COUNTA(实体字典!A4:A1177) -> 1174
A17: 绑定DCS位号数 | B17: =COUNTIF(关系明细!E2:E2253,"绑定测点") -> 622
A18: 覆盖工段数(有关系的工段) | B18: =COUNTIF('关系分类与统计(Overview)'!K33:K55,">0") -> 23

Sheet 全流程工段衔接
A1: 6-APA 全流程工段衔接（主流程 + 回收/公用支线）
A2: 主流程：发酵滤液 → S01/S02提取 → S05水洗 → S06脱色 → S07抽提 → S09薄膜 → S11酶法水解 → S12萃取 → S13/S14结晶 → S16干燥 → 6-APA成品；S03/S04/S10/S15为辅料配制，S08为钾盐副线，S17–S20为母液/溶媒/苯乙酸/废水回收，S22公用。
A4: 序号 | B4: 上游工段 | C4: 上游工段名称 | D4: → 衔接物料 | E4: 下游工段 | F4: 下游工段名称 | G4: 衔接说明（位号） | H4: 置信度
A5: 1 | B5: S03 | C5: 稀硫酸配制 | D5: 稀硫酸 | E5: S01 | F5: 提取·RSE300一/二萃 | G5: 稀硫酸经M2123在线混合器注入提取离心机进料 | H5: 高
A6: 2 | B6: S04 | C6: 破乳剂配制 | D6: 破乳剂溶液 | E6: S01 | F6: 提取·RSE300一/二萃 | G6: 破乳剂缓冲罐经破乳剂泵供RSE300/RSE200 | H6: 高
A7: 3 | B7: S01 | C7: 提取·RSE300一/二萃 | D7: 二级废酸水 | E7: S02 | F7: 提取·RSE200三萃及溶媒周转 | G7: RSE300重相（二级废酸水）送RSE200三萃 | H7: 高
A8: 4 | B8: S02 | C8: 提取·RSE200三萃及溶媒周转 | D8: 三萃BA | E8: S01 | F8: 提取·RSE300一/二萃 | G8: RSE200轻相（三萃BA）作为RSE300逆流萃取剂 | H8: 低
A9: 5 | B9: S01 | C9: 提取·RSE300一/二萃 | D9: 一次BA | E9: S05 | F9: BA水洗 | G9: 富青霉素一次BA经一次BA缓冲罐V2136送水洗离心机 | H9: 高
A10: 6 | B10: S05 | C10: BA水洗 | D10: 水洗重相 | E10: S01 | F10: 提取·RSE300一/二萃 | G10: 水洗重相罐物料返回提取回收青霉素 | H10: 高
A11: 7 | B11: S05 | C11: BA水洗 | D11: 水洗BA | E11: S06 | F11: 活性炭脱色与芬特过滤 | G11: 水洗BA罐V2142A/B经水洗BA泵送脱色罐 | H11: 高
A12: 8 | B12: S06 | C12: 活性炭脱色与芬特过滤 | D12: 脱色BA | E12: S07 | F12: 6APA抽提（碳酸钾反萃） | G12: 脱色BA储罐→去6A（FT_6A001） | H12: 高
A13: 9 | B13: S06 | C13: 活性炭脱色与芬特过滤 | D13: 脱色BA | E13: S08 | F13: 青霉素钾盐支线（点表补充） | G13: 脱色BA储罐→去钾盐（FT_JY001） | H13: 高
A14: 10 | B14: S07 | C14: 6APA抽提（碳酸钾反萃） | D14: 退BA（贫BA） | E14: S02 | F14: 提取·RSE200三萃及溶媒周转 | G14: 二阶轻相（6A退BA，FT_1215）返回丁酯罐 | H14: 高
A15: 11 | B15: S08 | C15: 青霉素钾盐支线（点表补充） | D15: 退BA（贫BA） | E15: S02 | F15: 提取·RSE200三萃及溶媒周转 | G15: 钾盐退BA（FT_1214）返回丁酯罐 | H15: 高
A16: 12 | B16: S07 | C16: 6APA抽提（碳酸钾反萃） | D16: RB液 | E16: S09 | F16: 薄膜蒸发（RB脱溶） | G16: 一阶重相RB液经FT_1316去薄膜 | H16: 高
... A44: 40 | B44: S22 | C44: 公用工程 | D44: 蒸汽/真空 | E44: S16 | F44: 6APA干燥 | G44: 干燥加热与真空 | H44: 中

Sheet 实体字典
A1: 本体实体字典（关系明细中出现的全部节点）
A3: 实体URI | B3: 实体语义名称 | C3: 实体类型 | D3: OWL类 | E3: 所属工段 | F3: 所属设备/流股 | G3: 说明 | H3: 作为主体次数 | I3: 作为客体次数
A4: :Area_S01_Extraction_RSE300 | B4: 提取·RSE300一/二萃 | C4: 生产工段 | D4: :ProductionArea | E4: S01 | G4: 发酵滤液在线加稀硫酸酸化、加破乳剂，与BA在RSE300碟片离心机上两阶段逆流萃取青霉素G | H4: =COUNTIF(关系明细!$D$2:$D$2253,B4) -> 8 | I4: =COUNTIF(关系明细!$G$2:$G$2253,B4) -> 4
A5: :AcidMixerM2123 | B5: 稀硫酸在线混合器M2123 | C5: 生产设备 | D5: :ProductionEquipment | E5: S01 | G5: 管道混合器；画面/位号：FT_1106A–E | H5: =COUNTIF(关系明细!$D$2:$D$2253,B5) -> 7 | I5: =COUNTIF(关系明细!$G$2:$G$2253,B5) -> 3
A6: :FiltratePumpGroup | B6: 滤液泵组 | C6: 生产设备 | D6: :ProductionEquipment | E6: S01 | G6: 泵；画面/位号：画面A–F泵 | H6: =COUNTIF(关系明细!$D$2:$D$2253,B6) -> 8 | I6: =COUNTIF(关系明细!$G$2:$G$2253,B6) -> 2
A7: :FiltrateTankGroup | B7: 发酵滤液储罐组 | C7: 生产设备 | D7: :ProductionEquipment | E7: S01 | G7: 储罐；画面/位号：LT_1102/TI_1101/FT_1103/FT_1004 | H7: =COUNTIF(关系明细!$D$2:$D$2253,B7) -> 8 | I7: =COUNTIF(关系明细!$G$2:$G$2253,B7) -> 3
A8: :RSE300CentrifugeGroup | B8: RSE300提取离心机组 | C8: 生产设备 | D8: :ProductionEquipment | E8: S01 | G8: 碟片离心机；画面/位号：II_10CQA–F | H8: =COUNTIF(关系明细!$D$2:$D$2253,B8) -> 25 | I8: =COUNTIF(关系明细!$G$2:$G$2253,B8) -> 7
A9: :WasteAcidNeutralizerV2124 | B9: 三级废酸水罐/废酸水中和罐V2124 | C9: 生产设备 | D9: :ProductionEquipment | E9: S01 | G9: 中和罐；画面/位号：LT_1105/AT_1111/HV_1101 | H9: =COUNTIF(关系明细!$D$2:$D$2253,B9) -> 7 | I9: =COUNTIF(关系明细!$G$2:$G$2253,B9) -> 3
A10: :WasteAcidTank2 | B10: 二级废酸水罐 | C10: 生产设备 | D10: :ProductionEquipment | E10: S01 | G10: 储罐；画面/位号：PT_1004（新增酸水罐） | H10: =COUNTIF(关系明细!$D$2:$D$2253,B10) -> 2 | I10: =COUNTIF(关系明细!$G$2:$G$2253,B10) -> 2
A11: :AcidMixerM2123_M01 | B11: M2123A | C11: 设备实例 | D11: :EquipmentInstance | E11: S01 | G11: 稀硫酸在线混合器M2123成员 | H11: =COUNTIF(关系明细!$D$2:$D$2253,B11) -> 0 | I11: =COUNTIF(关系明细!$G$2:$G$2253,B11) -> 1
A12: :AcidMixerM2123_M02 | B12: M2123B | C12: 设备实例 | D12: :EquipmentInstance | E12: S01 | G12: 稀硫酸在线混合器M2123成员 | H12: =COUNTIF(关系明细!$D$2:$D$2253,B12) -> 0 | I12: =COUNTIF(关系明细!$G$2:$G$2253,B12) -> 1
A13: :AcidMixerM2123_M03 | B13: M2123C | C13: 设备实例 | D13: :EquipmentInstance | E13: S01 | G13: 稀硫酸在线混合器M2123成员 | H13: =COUNTIF(关系明细!$D$2:$D$2253,B13) -> 0 | I13: =COUNTIF(关系明细!$G$2:$G$2253,B13) -> 1
A14: :AcidMixerM2123_M04 | B14: M2123D | C14: 设备实例 | D14: :EquipmentInstance | E14: S01 | G14: 稀硫酸在线混合器M2123成员 | H14: =COUNTIF(关系明细!$D$2:$D$2253,B14) -> 0 | I14: =COUNTIF(关系明细!$G$2:$G$2253,B14) -> 1
A15: :AcidMixerM2123_M05 | B15: M2123E | C15: 设备实例 | D15: :EquipmentInstance | E15: S01 | G15: 稀硫酸在线混合器M2123成员 | H15: =COUNTIF(关系明细!$D$2:$D$2253,B15) -> 0 | I15: =COUNTIF(关系明细!$G$2:$G$2253,B15) -> 1
... A43: :MS_WasteAcid2 | B43: 二级废酸水 | C43: 物料流股 | D43: :MaterialStream | E43: S01 | G43: RSE300重相，残余青霉素待三萃 | H43: =COUNTIF(关系明细!$D$2:$D$2253,B43) -> 2 | I43: =COUNTIF(关系明细!$G$2:$G$2253,B43) -> 1
A44: :Attr_001 | B44: 滤液罐液位 | C44: 工艺属性 | D44: :ProcessAttribute | E44: S01 | F44: 发酵滤液储罐组 | G44: 滤液储罐T2101液位 | H44: =COUNTIF(关系明细!$D$2:$D$2253,B44) -> 1 | I44: =COUNTIF(关系明细!$G$2:$G$2253,B44) -> 1
A45: :Attr_002 | B45: 滤液温度 | C45: 工艺属性 | D45: :ProcessAttribute | E45: S01 | F45: 发酵滤液储罐组 | G45: 滤液储罐温度，影响青霉素稳定性 | H45: =COUNTIF(关系明细!$D$2:$D$2253,B45) -> 2 | I45: =COUNTIF(关系明细!$G$2:$G$2253,B45) -> 2
A46: :Attr_003 | B46: 滤液罐进料流量 | C46: 工艺属性 | D46: :ProcessAttribute | E46: S01 | F46: 发酵滤液储罐组 | G46: 发酵滤液来料流量 | H46: =COUNTIF(关系明细!$D$2:$D$2253,B46) -> 3 | I46: =COUNTIF(关系明细!$G$2:$G$2253,B46) -> 1
A47: :Attr_004 | B47: 滤液进料流量 | C47: 工艺属性 | D47: :ProcessAttribute | E47: S01 | F47: RSE300提取离心机组 | G47: RSE300各组(1-2/3-4/5-6)滤液进料 | H47: =COUNTIF(关系明细!$D$2:$D$2253,B47) -> 4 | I47: =COUNTIF(关系明细!$G$2:$G$2253,B47) -> 2
A48: :Attr_005 | B48: BA进料流量 | C48: 工艺属性 | D48: :ProcessAttribute | E48: S01 | F48: RSE300提取离心机组 | G48: 丁酯/BA进料 | H48: =COUNTIF(关系明细!$D$2:$D$2253,B48) -> 5 | I48: =COUNTIF(关系明细!$G$2:$G$2253,B48) -> 3
A49: :Attr_006 | B49: 破乳剂进料流量 | C49: 工艺属性 | D49: :ProcessAttribute | E49: S01 | F49: RSE300提取离心机组 | G49: 破乳剂注入量 | H49: =COUNTIF(关系明细!$D$2:$D$2253,B49) -> 5 | I49: =COUNTIF(关系明细!$G$2:$G$2253,B49) -> 5
A50: :Attr_007 | B50: 一阶段酸化pH | C50: 工艺属性 | D50: :ProcessAttribute | E50: S01 | F50: RSE300提取离心机组 | G50: 一阶段萃取pH | H50: =COUNTIF(关系明细!$D$2:$D$2253,B50) -> 6 | I50: =COUNTIF(关系明细!$G$2:$G$2253,B50) -> 4
A51: :Attr_008 | B51: 二阶段酸化pH | C51: 工艺属性 | D51: :ProcessAttribute | E51: S01 | F51: RSE300提取离心机组 | G51: 二阶段萃取pH | H51: =COUNTIF(关系明细!$D$2:$D$2253,B51) -> 3 | I51: =COUNTIF(关系明细!$G$2:$G$2253,B51) -> 1
A52: :Attr_009 | B52: 重相出口压力 | C52: 工艺属性 | D52: :ProcessAttribute | E52: S01 | F52: RSE300提取离心机组 | G52: 重相向心泵背压 | H52: =COUNTIF(关系明细!$D$2:$D$2253,B52) -> 6 | I52: =COUNTIF(关系明细!$G$2:$G$2253,B52) -> 1
A53: :Attr_010 | B53: 轻相出口压力 | C53: 工艺属性 | D53: :ProcessAttribute | E53: S01 | F53: RSE300提取离心机组 | G53: 轻相向心泵背压 | H53: =COUNTIF(关系明细!$D$2:$D$2253,B53) -> 6 | I53: =COUNTIF(关系明细!$G$2:$G$2253,B53) -> 1
A54: :Attr_011 | B54: 主电机电流 | C54: 工艺属性 | D54: :ProcessAttribute | E54: S01 | F54: RSE300提取离心机组 | G54: 负荷/排渣状态指示 | H54: =COUNTIF(关系明细!$D$2:$D$2253,B54) -> 6 | I54: =COUNTIF(关系明细!$G$2:$G$2253,B54) -> 1
A55: :Attr_012 | B55: 稀硫酸注入流量 | C55: 工艺属性 | D55: :ProcessAttribute | E55: S01 | F55: 稀硫酸在线混合器M2123 | G55: 各混合器稀硫酸流量 | H55: =COUNTIF(关系明细!$D$2:$D$2253,B55) -> 6 | I55: =COUNTIF(关系明细!$G$2:$G$2253,B55) -> 1
... A62: :QKPI_253 | B62: 提取废酸水残效 | C62: 质量指标 | D62: :QualityKPI | E62: S01 | F62: 三级废酸水罐/废酸水中和罐V2124 | G62: 废酸水中残留青霉素，提取损失 | H62: =COUNTIF(关系明细!$D$2:$D$2253,B62) -> 1 | I62: =COUNTIF(关系明细!$G$2:$G$2253,B62) -> 4
A63: :Ctrl_001 | B63: 滤液进料流量控制器(FIC-1104) | C63: 控制仪表 | D63: :Controller | E63: S01 | G63: 按设定处理量调节离心机滤液进料 | H63: =COUNTIF(关系明细!$D$2:$D$2253,B63) -> 1 | I63: =COUNTIF(关系明细!$G$2:$G$2253,B63) -> 1
A64: :Ctrl_002 | B64: 破乳剂流量控制器(FIC-1101) | C64: 控制仪表 | D64: :Controller | E64: S01 | G64: 按滤液量比例投加破乳剂 | H64: =COUNTIF(关系明细!$D$2:$D$2253,B64) -> 1 | I64: =COUNTIF(关系明细!$G$2:$G$2253,B64) -> 1
A65: :Ctrl_003 | B65: 提取酸化pH控制器(AIC-1105) | C65: 控制仪表 | D65: :Controller | E65: S01 | G65: 调节稀硫酸泵频率使萃取pH稳定在2.0–2.2 | H65: =COUNTIF(关系明细!$D$2:$D$2253,B65) -> 1 | I65: =COUNTIF(关系明细!$G$2:$G$2253,B65) -> 1
A66: :Ctrl_004 | B66: BA进料流量控制器(FIC-1105) | C66: 控制仪表 | D66: :Controller | E66: S01 | G66: 按滤液流量维持相比 | H66: =COUNTIF(关系明细!$D$2:$D$2253,B66) -> 1 | I66: =COUNTIF(关系明细!$G$2:$G$2253,B66) -> 1
A67: :Ctrl_005 | B67: 废酸水中和pH控制器(AIC-1111) | C67: 控制仪表 | D67: :Controller | E67: S01 | G67: 液碱中和废酸水后外送 | H67: =COUNTIF(关系明细!$D$2:$D$2253,B67) -> 1 | I67: =COUNTIF(关系明细!$G$2:$G$2253,B67) -> 1
A68: :Act_001 | B68: 离心机滤液进口调节阀HV_1003A–E | C68: 执行机构 | D68: :Actuator | E68: S01 | G68: HV_1003A_AO、HV_1003B_AO、HV_1003C_AO、HV_1003D_AO、HV_1003E_AO | H68: =COUNTIF(关系明细!$D$2:$D$2253,B68) -> 2 | I68: =COUNTIF(关系明细!$G$2:$G$2253,B68) -> 1
A69: :Act_002 | B69: 破乳剂流量调节阀HV_1002A–F | C69: 执行机构 | D69: :Actuator | E69: S01 | G69: HV_1002A_AO、HV_1002B_AO、HV_1002C_AO、HV_1002D_AO、HV_1002E_AO、HV_1002F_AO | H69: =COUNTIF(关系明细!$D$2:$D$2253,B69) -> 2 | I69: =COUNTIF(关系明细!$G$2:$G$2253,B69) -> 1
A70: :Act_003 | B70: 稀硫酸泵变频器PB_1015A–F | C70: 执行机构 | D70: :Actuator | E70: S01 | G70: PB_1015A_AO、PB_1015B_AO、PB_1015C_AO、PB_1015D_AO、PB_1015E_AO、PB_1015F_AO | H70: =COUNTIF(关系明细!$D$2:$D$2253,B70) -> 1 | I70: =COUNTIF(关系明细!$G$2:$G$2253,B70) -> 1
A71: :Act_004 | B71: 离心机BA/丁酯进口调节阀HV_1004/HV_1005 | C71: 执行机构 | D71: :Actuator | E71: S01 | G71: HV_1004A_AO、HV_1005A_AO、HV_1004B_AO、HV_1005B_AO | H71: =COUNTIF(关系明细!$D$2:$D$2253,B71) -> 1 | I71: =COUNTIF(关系明细!$G$2:$G$2253,B71) -> 1
A72: :Act_005 | B72: 废酸水中和罐液碱调节阀HV_1101 | C72: 执行机构 | D72: :Actuator | E72: S01 | G72: HV_1101_AO | H72: =COUNTIF(关系明细!$D$2:$D$2253,B72) -> 1 | I72: =COUNTIF(关系明细!$G$2:$G$2253,B72) -> 1
A73: :Seq_01 | B73: 提取离心机顺控(全部启动/自动起停/急停) | C73: 控制系统 | D73: :ControlSystem | E73: S01 | G73: 画面“离心机启动/开始/急停/生产模式(二萃模式)” | H73: =COUNTIF(关系明细!$D$2:$D$2253,B73) -> 0 | I73: =COUNTIF(关系明细!$G$2:$G$2253,B73) -> 2
A74: :Alarm_01 | B74: 一次水流量报警 | C74: 报警事件 | D74: :AlarmEvent | E74: S01 | G74: 一次水异常影响提取供水 | H74: =COUNTIF(关系明细!$D$2:$D$2253,B74) -> 0 | I74: =COUNTIF(关系明细!$G$2:$G$2253,B74) -> 1
...

Sheet 关系分类与统计(Overview)
A1: 本体关系分类体系与统计总览（v2 全流程）
A2: 数量列为公式（COUNTIFS 关系明细），修改关系明细后自动刷新。
A3: 关系大类 (Category) | B3: 关系语义谓词 (Predicate) | C3: 关系含义 | D3: 典型主体类型 | E3: 典型客体类型 | F3: 关系数量
A4: 工段衔接 | B4: 串联下游 (connectedToNext) | C4: 工段之间物料/工艺衔接 | D4: 生产工段 | E4: 生产工段 | F4: =COUNTIFS(关系明细!$B$2:$B$2253,"工段衔接",关系明细!$E$2:$E$2253,"串联下游") -> 40
A5: 结构关系 | B5: 包含设备 (hasEquipment) | C5: 工段包含设备组 | D5: 生产工段 | E5: 生产设备 | F5: =COUNTIFS(关系明细!$B$2:$B$2253,"结构关系",关系明细!$E$2:$E$2253,"包含设备") -> 120
A6: 结构关系 | B6: 包含实例 (hasMember) | C6: 设备组包含编号实例 | D6: 生产设备 | E6: 设备实例 | F6: =COUNTIFS(关系明细!$B$2:$B$2253,"结构关系",关系明细!$E$2:$E$2253,"包含实例") -> 302
A7: 结构关系 | B7: 具有部件 (hasPart) | C7: 设备与机械/仪表组件的物理包含 | D7: 生产设备 | E7: 设备部件 | F7: =COUNTIFS(关系明细!$B$2:$B$2253,"结构关系",关系明细!$E$2:$E$2253,"具有部件") -> 223
A8: 结构关系 | B8: 具有属性 (hasAttribute) | C8: 设备/流股拥有的工艺参数或指标 | D8: 生产设备 / 物料流股 | E8: 工艺属性 / 质量指标 | F8: =COUNTIFS(关系明细!$B$2:$B$2253,"结构关系",关系明细!$E$2:$E$2253,"具有属性") -> 335
A9: 测点绑定关系 | B9: 绑定测点 (boundToTag) | C9: 工艺属性绑定到DCS位号 | D9: 工艺属性 | E9: DCS测点 | F9: =COUNTIFS(关系明细!$B$2:$B$2253,"测点绑定关系",关系明细!$E$2:$E$2253,"绑定测点") -> 622
A10: 控制关系 | B10: 控制 (controls) | C10: 控制器驱动执行机构 | D10: 控制仪表 | E10: 执行机构 | F10: =COUNTIFS(关系明细!$B$2:$B$2253,"控制关系",关系明细!$E$2:$E$2253,"控制") -> 59
A11: 控制关系 | B11: 反馈给 (feedbackTo) | C11: 测量属性作为PV回传控制器 | D11: 工艺属性 | E11: 控制仪表 | F11: =COUNTIFS(关系明细!$B$2:$B$2253,"控制关系",关系明细!$E$2:$E$2253,"反馈给") -> 59
A12: 控制关系 | B12: 影响 (affects) | C12: 执行机构动作改变被控属性 | D12: 执行机构 | E12: 工艺属性 | F12: =COUNTIFS(关系明细!$B$2:$B$2253,"控制关系",关系明细!$E$2:$E$2253,"影响") -> 59
A13: 控制关系 | B13: 被控制 (isControlledBy) | C13: 设备/阀门受顺控/批次程序控制 | D13: 执行机构 / 生产设备 | E13: 控制系统 | F13: =COUNTIFS(关系明细!$B$2:$B$2253,"控制关系",关系明细!$E$2:$E$2253,"被控制") -> 15
A14: 报警联锁关系 | B14: 触发报警 (triggersAlarm) | C14: 属性越限触发报警/联锁 | D14: 工艺属性 | E14: 报警事件 | F14: =COUNTIFS(关系明细!$B$2:$B$2253,"报警联锁关系",关系明细!$E$2:$E$2253,"触发报警") -> 15
A15: 物理拓扑关系 | B15: 流入 (flowsInto) | C15: 物料流向设备 | D15: 物料流股 | E15: 生产设备 | F15: =COUNTIFS(关系明细!$B$2:$B$2253,"物理拓扑关系",关系明细!$E$2:$E$2253,"流入") -> 67
A16: 物理拓扑关系 | B16: 注入 (injectedInto) | C16: 酸/碱/助剂注入（flowsInto子属性） | D16: 物料流股 | E16: 生产设备 | F16: =COUNTIFS(关系明细!$B$2:$B$2253,"物理拓扑关系",关系明细!$E$2:$E$2253,"注入") -> 12
A17: 物理拓扑关系 | B17: 滴加入 (dosedInto) | C17: 按控制量滴加（flowsInto子属性） | D17: 物料流股 | E17: 生产设备 | F17: =COUNTIFS(关系明细!$B$2:$B$2253,"物理拓扑关系",关系明细!$E$2:$E$2253,"滴加入") -> 1
A18: 物理拓扑关系 | B18: 循环返回 (recyclesTo) | C18: 回收/逆流/套用物料返回（flowsInto子属性） | D18: 物料流股 | E18: 生产设备 | F18: =COUNTIFS(关系明细!$B$2:$B$2253,"物理拓扑关系",关系明细!$E$2:$E$2253,"循环返回") -> 4
A19: 物理拓扑关系 | B19: 供给介质 (suppliesUtility) | C19: 蒸汽/冷盐水/真空/仪表气供给 | D19: 公用介质 | E19: 生产设备 | F19: =COUNTIFS(关系明细!$B$2:$B$2253,"物理拓扑关系",关系明细!$E$2:$E$2253,"供给介质") -> 19
A20: 物理拓扑关系 | B20: 产出 (produces) | C20: 反应/配制单元产出流股 | D20: 生产设备 | E20: 物料流股 | F20: =COUNTIFS(关系明细!$B$2:$B$2253,"物理拓扑关系",关系明细!$E$2:$E$2253,"产出") -> 37
A21: 物理拓扑关系 | B21: 分离产出 (separatesInto) | C21: 分离单元产出轻/重相（produces子属性） | D21: 生产设备 | E21: 物料流股 | F21: =COUNTIFS(关系明细!$B$2:$B$2253,"物理拓扑关系",关系明细!$E$2:$E$2253,"分离产出") -> 21
A22: 物理拓扑关系 | B22: 串联下游 (connectedToNext) | C22: 设备直接物理串联 | D22: 生产设备 | E22: 生产设备 | F22: =COUNTIFS(关系明细!$B$2:$B$2253,"物理拓扑关系",关系明细!$E$2:$E$2253,"串联下游") -> 85
A23: 影响关系 | B23: 正向影响 (positivelyAffects) | C23: 前项升高驱动后项升高 | D23: 工艺属性 | E23: 工艺属性 / 质量指标 | F23: =COUNTIFS(关系明细!$B$2:$B$2253,"影响关系",关系明细!$E$2:$E$2253,"正向影响") -> 47
A24: 影响关系 | B24: 负向影响 (negativelyAffects) | C24: 前项升高导致后项降低/恶化 | D24: 工艺属性 | E24: 工艺属性 / 质量指标 | F24: =COUNTIFS(关系明细!$B$2:$B$2253,"影响关系",关系明细!$E$2:$E$2253,"负向影响") -> 41
A25: 影响关系 | B25: 影响 (affects) | C25: 非单调/双向耦合影响 | D25: 工艺属性 | E25: 工艺属性 | F25: =COUNTIFS(关系明细!$B$2:$B$2253,"影响关系",关系明细!$E$2:$E$2253,"影响") -> 35
A26: 质量关系 | B26: 正向影响 (positivelyAffects) | C26: 指标对收率/质量的正向贡献 | D26: 质量指标 / 工艺属性 | E26: 业务指标 / 质量指标 | F26: =COUNTIFS(关系明细!$B$2:$B$2253,"质量关系",关系明细!$E$2:$E$2253,"正向影响") -> 18
A27: 质量关系 | B27: 负向影响 (negativelyAffects) | C27: 损失/残留对收率/质量的负向作用 | D27: 质量指标 / 工艺属性 | E27: 业务指标 / 质量指标 | F27: =COUNTIFS(关系明细!$B$2:$B$2253,"质量关系",关系明细!$E$2:$E$2253,"负向影响") -> 16
A28: 合计 | F28: =SUM(F4:F27) -> 2252
A29: 核对 | F29: =COUNTA(关系明细!$L$2:$L$2253) -> 2252
A31: 工段 × 关系大类 分布
A32: 工段编号 | B32: 工段 | C32: 工段衔接 | D32: 结构关系 | E32: 测点绑定关系 | F32: 控制关系 | G32: 报警联锁关系 | H32: 物理拓扑关系 | I32: 影响关系 | J32: 质量关系 | K32: 合计 | L32: 高置信占比
A33: S01 | B33: 提取·RSE300一/二萃 | C33: =COUNTIFS(关系明细!$K$2:$K$2253,$A33,关系明细!$B$2:$B$2253,"工段衔接") -> 2 | D33: =COUNTIFS(关系明细!$K$2:$K$2253,$A33,关系明细!$B$2:$B$2253,"结构关系") -> 57 | E33: =COUNTIFS(关系明细!$K$2:$K$2253,$A33,关系明细!$B$2:$B$2253,"测点绑定关系") -> 44 | F33: =COUNTIFS(关系明细!$K$2:$K$2253,$A33,关系明细!$B$2:$B$2253,"控制关系") -> 17 | G33: =COUNTIFS(关系明细!$K$2:$K$2253,$A33,关系明细!$B$2:$B$2253,"报警联锁关系") -> 2 | H33: =COUNTIFS(关系明细!$K$2:$K$2253,$A33,关系明细!$B$2:$B$2253,"物理拓扑关系") -> 16 | I33: =COUNTIFS(关系明细!$K$2:$K$2253,$A33,关系明细!$B$2:$B$2253,"影响关系") -> 12 | J33: =COUNTIFS(关系明细!$K$2:$K$2253,$A33,关系明细!$B$2:$B$2253,"质量关系") -> 3 | K33: =SUM(C33:J33) -> 153 | L33: =IF(K33=0,0,COUNTIFS(关系明细!$K$2:$K$2253,$A33,关系明细!$R$2:$R$2253,"高")/K33) -> 0.77124183
A34: S02 | B34: 提取·RSE200三萃及溶媒周转 | C34: =COUNTIFS(关系明细!$K$2:$K$2253,$A34,关系明细!$B$2:$B$2253,"工段衔接") -> 2 | D34: =COUNTIFS(关系明细!$K$2:$K$2253,$A34,关系明细!$B$2:$B$2253,"结构关系") -> 38 | E34: =COUNTIFS(关系明细!$K$2:$K$2253,$A34,关系明细!$B$2:$B$2253,"测点绑定关系") -> 29 | F34: =COUNTIFS(关系明细!$K$2:$K$2253,$A34,关系明细!$B$2:$B$2253,"控制关系") -> 7 | G34: =COUNTIFS(关系明细!$K$2:$K$2253,$A34,关系明细!$B$2:$B$2253,"报警联锁关系") -> 0 | H34: =COUNTIFS(关系明细!$K$2:$K$2253,$A34,关系明细!$B$2:$B$2253,"物理拓扑关系") -> 11 | I34: =COUNTIFS(关系明细!$K$2:$K$2253,$A34,关系明细!$B$2:$B$2253,"影响关系") -> 4 | J34: =COUNTIFS(关系明细!$K$2:$K$2253,$A34,关系明细!$B$2:$B$2253,"质量关系") -> 0 | K34: =SUM(C34:J34) -> 91 | L34: =IF(K34=0,0,COUNTIFS(关系明细!$K$2:$K$2253,$A34,关系明细!$R$2:$R$2253,"高")/K34) -> 0.76923077
A35: S03 | B35: 稀硫酸配制 | C35: =COUNTIFS(关系明细!$K$2:$K$2253,$A35,关系明细!$B$2:$B$2253,"工段衔接") -> 1 | D35: =COUNTIFS(关系明细!$K$2:$K$2253,$A35,关系明细!$B$2:$B$2253,"结构关系") -> 36 | E35: =COUNTIFS(关系明细!$K$2:$K$2253,$A35,关系明细!$B$2:$B$2253,"测点绑定关系") -> 18 | F35: =COUNTIFS(关系明细!$K$2:$K$2253,$A35,关系明细!$B$2:$B$2253,"控制关系") -> 0 | G35: =COUNTIFS(关系明细!$K$2:$K$2253,$A35,关系明细!$B$2:$B$2253,"报警联锁关系") -> 1 | H35: =COUNTIFS(关系明细!$K$2:$K$2253,$A35,关系明细!$B$2:$B$2253,"物理拓扑关系") -> 7 | I35: =COUNTIFS(关系明细!$K$2:$K$2253,$A35,关系明细!$B$2:$B$2253,"影响关系") -> 2 | J35: =COUNTIFS(关系明细!$K$2:$K$2253,$A35,关系明细!$B$2:$B$2253,"质量关系") -> 0 | K35: =SUM(C35:J35) -> 65 | L35: =IF(K35=0,0,COUNTIFS(关系明细!$K$2:$K$2253,$A35,关系明细!$R$2:$R$2253,"高")/K35) -> 0.90769231
A36: S04 | B36: 破乳剂配制 | C36: =COUNTIFS(关系明细!$K$2:$K$2253,$A36,关系明细!$B$2:$B$2253,"工段衔接") -> 1 | D36: =COUNTIFS(关系明细!$K$2:$K$2253,$A36,关系明细!$B$2:$B$2253,"结构关系") -> 19 | E36: =COUNTIFS(关系明细!$K$2:$K$2253,$A36,关系明细!$B$2:$B$2253,"测点绑定关系") -> 8 | F36: =COUNTIFS(关系明细!$K$2:$K$2253,$A36,关系明细!$B$2:$B$2253,"控制关系") -> 1 | G36: =COUNTIFS(关系明细!$K$2:$K$2253,$A36,关系明细!$B$2:$B$2253,"报警联锁关系") -> 1 | H36: =COUNTIFS(关系明细!$K$2:$K$2253,$A36,关系明细!$B$2:$B$2253,"物理拓扑关系") -> 8 | I36: =COUNTIFS(关系明细!$K$2:$K$2253,$A36,关系明细!$B$2:$B$2253,"影响关系") -> 2 | J36: =COUNTIFS(关系明细!$K$2:$K$2253,$A36,关系明细!$B$2:$B$2253,"质量关系") -> 0 | K36: =SUM(C36:J36) -> 40 | L36: =IF(K36=0,0,COUNTIFS(关系明细!$K$2:$K$2253,$A36,关系明细!$R$2:$R$2253,"高")/K36) -> 0.775
A37: S05 | B37: BA水洗 | C37: =COUNTIFS(关系明细!$K$2:$K$2253,$A37,关系明细!$B$2:$B$2253,"工段衔接") -> 2 | D37: =COUNTIFS(关系明细!$K$2:$K$2253,$A37,关系明细!$B$2:$B$2253,"结构关系") -> 38 | E37: =COUNTIFS(关系明细!$K$2:$K$2253,$A37,关系明细!$B$2:$B$2253,"测点绑定关系") -> 31 | F37: =COUNTIFS(关系明细!$K$2:$K$2253,$A37,关系明细!$B$2:$B$2253,"控制关系") -> 6 | G37: =COUNTIFS(关系明细!$K$2:$K$2253,$A37,关系明细!$B$2:$B$2253,"报警联锁关系") -> 1 | H37: =COUNTIFS(关系明细!$K$2:$K$2253,$A37,关系明细!$B$2:$B$2253,"物理拓扑关系") -> 10 | I37: =COUNTIFS(关系明细!$K$2:$K$2253,$A37,关系明细!$B$2:$B$2253,"影响关系") -> 3 | J37: =COUNTIFS(关系明细!$K$2:$K$2253,$A37,关系明细!$B$2:$B$2253,"质量关系") -> 1 | K37: =SUM(C37:J37) -> 92 | L37: =IF(K37=0,0,COUNTIFS(关系明细!$K$2:$K$2253,$A37,关系明细!$R$2:$R$2253,"高")/K37) -> 0.79347826
A38: S06 | B38: 活性炭脱色与芬特过滤 | C38: =COUNTIFS(关系明细!$K$2:$K$2253,$A38,关系明细!$B$2:$B$2253,"工段衔接") -> 2 | D38: =COUNTIFS(关系明细!$K$2:$K$2253,$A38,关系明细!$B$2:$B$2253,"结构关系") -> 55 | E38: =COUNTIFS(关系明细!$K$2:$K$2253,$A38,关系明细!$B$2:$B$2253,"测点绑定关系") -> 29 | F38: =COUNTIFS(关系明细!$K$2:$K$2253,$A38,关系明细!$B$2:$B$2253,"控制关系") -> 8 | G38: =COUNTIFS(关系明细!$K$2:$K$2253,$A38,关系明细!$B$2:$B$2253,"报警联锁关系") -> 3 | H38: =COUNTIFS(关系明细!$K$2:$K$2253,$A38,关系明细!$B$2:$B$2253,"物理拓扑关系") -> 14 | I38: =COUNTIFS(关系明细!$K$2:$K$2253,$A38,关系明细!$B$2:$B$2253,"影响关系") -> 5 | J38: =COUNTIFS(关系明细!$K$2:$K$2253,$A38,关系明细!$B$2:$B$2253,"质量关系") -> 2 | K38: =SUM(C38:J38) -> 118 | L38: =IF(K38=0,0,COUNTIFS(关系明细!$K$2:$K$2253,$A38,关系明细!$R$2:$R$2253,"高")/K38) -> 0.72881356
A39: S07 | B39: 6APA抽提（碳酸钾反萃） | C39: =COUNTIFS(关系明细!$K$2:$K$2253,$A39,关系明细!$B$2:$B$2253,"工段衔接") -> 2 | D39: =COUNTIFS(关系明细!$K$2:$K$2253,$A39,关系明细!$B$2:$B$2253,"结构关系") -> 78 | E39: =COUNTIFS(关系明细!$K$2:$K$2253,$A39,关系明细!$B$2:$B$2253,"测点绑定关系") -> 49 | F39: =COUNTIFS(关系明细!$K$2:$K$2253,$A39,关系明细!$B$2:$B$2253,"控制关系") -> 21 | G39: =COUNTIFS(关系明细!$K$2:$K$2253,$A39,关系明细!$B$2:$B$2253,"报警联锁关系") -> 0 | H39: =COUNTIFS(关系明细!$K$2:$K$2253,$A39,关系明细!$B$2:$B$2253,"物理拓扑关系") -> 18 | I39: =COUNTIFS(关系明细!$K$2:$K$2253,$A39,关系明细!$B$2:$B$2253,"影响关系") -> 7 | J39: =COUNTIFS(关系明细!$K$2:$K$2253,$A39,关系明细!$B$2:$B$2253,"质量关系") -> 1 | K39: =SUM(C39:J39) -> 176 | L39: =IF(K39=0,0,COUNTIFS(关系明细!$K$2:$K$2253,$A39,关系明细!$R$2:$R$2253,"高")/K39) -> 0.77840909
A40: S08 | B40: 青霉素钾盐支线（点表补充） | C40: =COUNTIFS(关系明细!$K$2:$K$2253,$A40,关系明细!$B$2:$B$2253,"工段衔接") -> 2 | D40: =COUNTIFS(关系明细!$K$2:$K$2253,$A40,关系明细!$B$2:$B$2253,"结构关系") -> 42 | E40: =COUNTIFS(关系明细!$K$2:$K$2253,$A40,关系明细!$B$2:$B$2253,"测点绑定关系") -> 26 | F40: =COUNTIFS(关系明细!$K$2:$K$2253,$A40,关系明细!$B$2:$B$2253,"控制关系") -> 9 | G40: =COUNTIFS(关系明细!$K$2:$K$2253,$A40,关系明细!$B$2:$B$2253,"报警联锁关系") -> 0 | H40: =COUNTIFS(关系明细!$K$2:$K$2253,$A40,关系明细!$B$2:$B$2253,"物理拓扑关系") -> 10 | I40: =COUNTIFS(关系明细!$K$2:$K$2253,$A40,关系明细!$B$2:$B$2253,"影响关系") -> 2 | J40: =COUNTIFS(关系明细!$K$2:$K$2253,$A40,关系明细!$B$2:$B$2253,"质量关系") -> 0 | K40: =SUM(C40:J40) -> 91 | L40: =IF(K40=0,0,COUNTIFS(关系明细!$K$2:$K$2253,$A40,关系明细!$R$2:$R$2253,"高")/K40) -> 0.81318681
A41: S09 | B41: 薄膜蒸发（RB脱溶） | C41: =COUNTIFS(关系明细!$K$2:$K$2253,$A41,关系明细!$B$2:$B$2253,"工段衔接") -> 2 | D41: =COUNTIFS(关系明细!$K$2:$K$2253,$A41,关系明细!$B$2:$B$2253,"结构关系") -> 64 | E41: =COUNTIFS(关系明细!$K$2:$K$2253,$A41,关系明细!$B$2:$B$2253,"测点绑定关系") -> 40 | F41: =COUNTIFS(关系明细!$K$2:$K$2253,$A41,关系明细!$B$2:$B$2253,"控制关系") -> 10 | G41: =COUNTIFS(关系明细!$K$2:$K$2253,$A41,关系明细!$B$2:$B$2253,"报警联锁关系") -> 1 | H41: =COUNTIFS(关系明细!$K$2:$K$2253,$A41,关系明细!$B$2:$B$2253,"物理拓扑关系") -> 14 | I41: =COUNTIFS(关系明细!$K$2:$K$2253,$A41,关系明细!$B$2:$B$2253,"影响关系") -> 9 | J41: =COUNTIFS(关系明细!$K$2:$K$2253,$A41,关系明细!$B$2:$B$2253,"质量关系") -> 3 | K41: =SUM(C41:J41) -> 143 | L41: =IF(K41=0,0,COUNTIFS(关系明细!$K$2:$K$2253,$A41,关系明细!$R$2:$R$2253,"高")/K41) -> 0.75524476
...

Sheet OWL_Turtle代码规范
A1: W3C OWL / Turtle 三元组（v2 全流程，自动由关系明细生成；完整文件见同目录 6APA_ontology_全流程.ttl）
A3: @prefix : <http://pharma.ontology.org/antibiotics/6apa#> .
A4: @prefix owl: <http://www.w3.org/2002/07/owl#> .
A5: @prefix rdf: <http://www.w3.org/1999/02/22-rdf-syntax-ns#> .
A6: @prefix rdfs: <http://www.w3.org/2000/01/rdf-schema#> .
A7: @prefix xsd: <http://www.w3.org/2001/XMLSchema#> .
A9: <http://pharma.ontology.org/antibiotics/6apa> a owl:Ontology ; rdfs:label '6-APA车间全流程工业本体 v2'@zh .
A11: # === 1. 类 (Classes) ===
A12: :ProductionArea a owl:Class ; rdfs:label '生产工段'@zh .
A13: :ProductionEquipment a owl:Class ; rdfs:label '生产设备'@zh .
A14: :EquipmentInstance a owl:Class ; rdfs:label '设备实例'@zh .
A15: :EquipmentComponent a owl:Class ; rdfs:label '设备部件'@zh .
... A4132: :QKPI_283 :negativelyAffects :BKPI_304 . # R2252 废有机相6-APA夹带残效 -负向影响-> 全厂批次最终提取收率

Sheet v1→v2修订记录
A1: 原关系（v1，71条）逐条处理记录
A2: 原文件萃取工段将“水洗碟片离心机组+稀硫酸+醋酸丁酯+破乳剂”作为萃取主体，与流程图不符： 稀硫酸/破乳剂/丁酯属于提取工段(RSE300/RSE200)；萃取工段(萃取画面)为“萃取离心机A–J + 盐酸 + 混合溶媒”，轻相先去反萃再回收，而非直接去苯乙酸精馏。
A4: 原行号 | B4: 原工段 | C4: 原三元组 | D4: 处理 | E4: v2三元组 | F4: v2关系ID | G4: 修订依据
A5: 2 | B5: 水解工段 | C5: 水解反应釜 —具有部件→ 夹套换热系统 | D5: 修订 | E5: 水解反应釜组(水解罐A–K) —具有部件→ 水解反应釜组(水解罐A–K)·夹套换热系统 | F5: R1064
A6: 3 | B6: 水解工段 | C6: 水解反应釜 —具有部件→ 机械搅拌装置 | D6: 修订 | E6: 水解反应釜组(水解罐A–K) —具有部件→ 水解反应釜组(水解罐A–K)·机械搅拌装置 | F6: R1065
A7: 4 | B7: 水解工段 | C7: 水解反应釜 —具有属性→ 釜内反应温度 | D7: 修订 | E7: 水解反应釜组(水解罐A–K) —具有属性→ 釜内反应温度 | F7: R1095
A8: 5 | B8: 水解工段 | C8: 水解反应釜 —具有属性→ 反应体系pH | D8: 修订 | E8: 水解反应釜组(水解罐A–K) —具有属性→ 反应体系pH | F8: R1096
A9: 6 | B9: 水解工段 | C9: 水解反应釜 —具有属性→ 釜内反应液位 | D9: 修订 | E9: 水解反应釜组(水解罐A–K) —具有属性→ 釜内反应液位 | F9: R1097
A10: 7 | B10: 水解工段 | C10: 水解反应釜 —具有属性→ 搅拌运行转速 | D10: 修订 | E10: 水解反应釜组(水解罐A–K) —具有属性→ 搅拌运行状态 | F10: R1098 | G10: 点表仅有水解罐搅拌启停/运行状态（P_1303x），无转速测点
A11: 8 | B11: 水解工段 | C11: RB浓缩原料液 —具有属性→ RB进料温度 | D11: 修订 | E11: 脱溶RB液 —具有属性→ RB进料温度 | F11: R0888 | G11: 统一为“脱溶RB液”（薄膜脱溶后），与上游“RB液”区分
A12: 9 | B12: 水解工段 | C12: RB浓缩原料液 —具有属性→ RB进料流量 | D12: 修订 | E12: 脱溶RB液 —具有属性→ RB进料流量 | F12: R0889 | G12: 统一为“脱溶RB液”（薄膜脱溶后），与上游“RB液”区分
A13: 10 | B13: 水解工段 | C13: 硼酸缓冲液 —具有属性→ 硼酸溶液温度 | D13: 保留 | E13: 硼酸缓冲液 —具有属性→ 硼酸溶液温度 | F13: R1016 | G13: 名称统一
A14: 11 | B14: 水解工段 | C14: 硼酸缓冲液 —具有属性→ 硼酸进料流量 | D14: 保留 | E14: 硼酸缓冲液 —具有属性→ 硼酸进料流量 | F14: R1017 | G14: 名称统一
A15: 12 | B15: 水解工段 | C15: 中和氨水 —具有属性→ 氨水加料流量 | D15: 修订 | E15: 中和氨水 —具有属性→ 氨水累计加量 | F15: R1018
A16: 13 | B16: 水解工段 | C16: pH指示控制器(AIC) —控制→ 氨水加料气动调节阀 | D16: 修订 | E16: 水解pH指示控制器(AIC-1301) —控制→ 氨水调节阀HV_1302 | F16: R1182
A17: 14 | B17: 水解工段 | C17: 反应体系pH —反馈给→ pH指示控制器(AIC) | D17: 修订 | E17: 反应体系pH —反馈给→ 水解pH指示控制器(AIC-1301) | F17: R1183
A18: 15 | B18: 水解工段 | C18: 温度指示控制器(TIC) —控制→ 夹套伴热蒸汽/冷水调节阀 | D18: 修订 | E18: 水解温度指示控制器(TIC-1301) —控制→ 热水阀HV_1301 | F18: R1185
A19: 16 | B19: 水解工段 | C19: 釜内反应温度 —反馈给→ 温度指示控制器(TIC) | D19: 修订 | E19: 釜内反应温度 —反馈给→ 水解温度指示控制器(TIC-1301) | F19: R1186
A20: 17 | B20: 水解工段 | C20: 水解罐进出料气动切断阀 —被控制→ 连续水解批次调度程序(SFC) | D20: 保留 | E20: 水解罐进出料气动切断阀 —被控制→ 连续水解批次调度程序(SFC) | F20: R1203 | G20: 名称统一
A21: 18 | B21: 水解工段 | C21: RB浓缩原料液 —流入→ 水解反应釜 | D21: 修订 | E21: 脱溶RB液 —流入→ 水解反应釜组(水解罐A–K) | F21: R1211 | G21: 统一为“脱溶RB液”（薄膜脱溶后），与上游“RB液”区分
A22: 19 | B22: 水解工段 | C22: 硼酸缓冲液 —流入→ 水解反应釜 | D22: 修订 | E22: 硼酸缓冲液 —流入→ 水解反应釜组(水解罐A–K) | F22: R1212
A23: 20 | B23: 水解工段 | C23: 中和氨水 —滴加入→ 水解反应釜 | D23: 修订 | E23: 中和氨水 —滴加入→ 水解反应釜组(水解罐A–K) | F23: R1213
A24: 21 | B24: 水解工段 | C24: 水解反应釜 —产出→ 酶解水解反应液 | D24: 修订 | E24: 水解反应釜组(水解罐A–K) —产出→ 酶解水解反应液 | F24: R1216
A25: 22 | B25: 水解工段 | C25: 酶解水解反应液 —流入→ 水解田缓冲罐 | D25: 修订 | E25: 酶解水解反应液 —流入→ 水解液缓冲罐 | F25: R1217 | G25: 笔误，应为水解液缓冲罐（LT_1303）
A26: 23 | B26: 水解工段 | C26: 热水罐出水温度 —正向影响→ RB进料温度 | D26: 保留 | E26: 热水罐出水温度 —正向影响→ RB进料温度 | F26: R1219 | G26: 名称统一
A27: 24 | B27: 水解工段 | C27: RB进料温度 —正向影响→ 釜内反应温度 | D27: 保留 | E27: RB进料温度 —正向影响→ 釜内反应温度 | F27: R1220 | G27: 名称统一
A28: 25 | B28: 水解工段 | C28: 硼酸溶液温度 —正向影响→ 釜内反应温度 | D28: 保留 | E28: 硼酸溶液温度 —正向影响→ 釜内反应温度 | F28: R1048 | G28: 名称统一
A29: 26 | B29: 水解工段 | C29: 夹套伴热蒸汽流量 —正向影响→ 釜内反应温度 | D29: 修订 | E29: 夹套热水/蒸汽加热量 —正向影响→ 釜内反应温度 | F29: R1235
A30: 27 | B30: 水解工段 | C30: 釜内反应温度 —负向影响→ 固定化酶活力稳定性 | D30: 保留 | E30: 釜内反应温度 —负向影响→ 固定化酶活力稳定性 | F30: R1221 | G30: 名称统一
A31: 28 | B31: 水解工段 | C31: 釜内反应温度 —负向影响→ 6-APA热降解损失率 | D31: 保留 | E31: 釜内反应温度 —负向影响→ 6-APA热降解损失率 | F31: R1222 | G31: 名称统一
A32: 29 | B32: 水解工段 | C32: 氨水加料流量 —正向影响→ 反应体系pH | D32: 修订 | E32: 氨水累计加量 —正向影响→ 反应体系pH | F32: R1226
A33: 30 | B33: 水解工段 | C33: 反应体系pH —正向影响→ 酶催化水解反应速率 | D33: 修订 | E33: 反应体系pH —影响→ 酶催化水解反应速率 | F33: R1224 | G33: pH对酶反应速率为钟形（最适7.8–8.2）非单调关系，谓词由“正向影响”改为“影响”
A34: 31 | B34: 水解工段 | C34: 搅拌运行转速 —正向影响→ 固液传质速率 | D34: 修订 | E34: 搅拌运行状态 —正向影响→ 固液传质速率 | F34: R1230 | G34: 点表仅有水解罐搅拌启停/运行状态（P_1303x），无转速测点
A35: 32 | B35: 水解工段 | C35: 搅拌运行转速 —负向影响→ 固定化酶载体寿命 | D35: 修订 | E35: 搅拌运行状态 —负向影响→ 固定化酶载体寿命 | F35: R1231 | G35: 点表仅有水解罐搅拌启停/运行状态（P_1303x），无转速测点
A36: 33 | B36: 水解工段 | C36: 酶催化水解反应速率 —正向影响→ 水解酶解转化率 | D36: 保留 | E36: 酶催化水解反应速率 —正向影响→ 水解酶解转化率 | F36: R1236 | G36: 名称统一
A37: 34 | B37: 水解工段 | C37: 固定化酶活力稳定性 —正向影响→ 水解酶解转化率 | D37: 保留 | E37: 固定化酶活力稳定性 —正向影响→ 水解酶解转化率 | F37: R1237 | G37: 名称统一
A38: 35 | B38: 水解工段 | C38: 水解酶解转化率 —正向影响→ 产品批次提取收率 | D38: 保留 | E38: 水解酶解转化率 —正向影响→ 产品批次提取收率 | F38: R1239 | G38: 名称统一
A39: 36 | B39: 萃取工段 | C39: 水洗碟片离心机组 —具有部件→ 碟片分离转鼓 | D39: 修订 | E39: 一萃离心机组 —具有部件→ 一萃离心机组·碟片分离转鼓 | F39: R1267 | G39: 流程图中“水洗离心机”属提取水洗段(BA水洗)；萃取工段使用萃取离心机A–J（一萃A–D/二萃E–H/反萃I–J）
A40: 37 | B40: 萃取工段 | C40: 水洗碟片离心机组 —具有属性→ 离心机转速 | D40: 修订 | E40: 一萃离心机组 —具有属性→ 萃取离心机转速 | F40: R1334 | G40: 流程图中“水洗离心机”属提取水洗段(BA水洗)；萃取工段使用萃取离心机A–J（一萃A–D/二萃E–H/反萃I–J）
A41: 38 | B41: 萃取工段 | C41: 水洗碟片离心机组 —具有属性→ 轻相出口背压 | D41: 修订 | E41: 一萃离心机组 —具有属性→ 萃取离心机轻相背压 | F41: R1335 | G41: 流程图中“水洗离心机”属提取水洗段(BA水洗)；萃取工段使用萃取离心机A–J（一萃A–D/二萃E–H/反萃I–J）
...

Sheet 原关系明细(v1存档)
A1: 工段 (Area) | B1: 关系大类 (Category) | C1: 起始对象类型 (Subject Type) | D1: 起始对象语义名称 (Subject Entity) | E1: 关系谓词 / 边类型 (Predicate) | F1: 目标对象类型 (Object Type) | G1: 目标对象语义名称 (Object Entity) | H1: 工艺机理与业务因果说明 (Domain Description) | I1: 子场景 | J1: 权重
A2: 水解工段 | B2: 结构关系 | C2: 生产设备 | D2: 水解反应釜 | E2: 具有部件 | F2: 设备部件 | G2: 夹套换热系统 | H2: 水解罐配置温控夹套用于反应控温 | I2: 常态 | J2: 1
A3: 水解工段 | B3: 结构关系 | C3: 生产设备 | D3: 水解反应釜 | E3: 具有部件 | F3: 设备部件 | G3: 机械搅拌装置 | H3: 水解罐配置搅拌电机与桨叶提供混合剪切 | I3: 常态 | J3: 1
A4: 水解工段 | B4: 结构关系 | C4: 生产设备 | D4: 水解反应釜 | E4: 具有属性 | F4: 工艺属性 | G4: 釜内反应温度 | H4: 水解反应釜内部反应温度 | I4: 常态 | J4: 1
A5: 水解工段 | B5: 结构关系 | C5: 生产设备 | D5: 水解反应釜 | E5: 具有属性 | F5: 工艺属性 | G5: 反应体系pH | H5: 水解反应釜内部pH值 | I5: 常态 | J5: 1
A6: 水解工段 | B6: 结构关系 | C6: 生产设备 | D6: 水解反应釜 | E6: 具有属性 | F6: 工艺属性 | G6: 釜内反应液位 | H6: 水解反应釜物料液位 | I6: 常态 | J6: 1
A7: 水解工段 | B7: 结构关系 | C7: 生产设备 | D7: 水解反应釜 | E7: 具有属性 | F7: 工艺属性 | G7: 搅拌运行转速 | H7: 反应釜搅拌电机转速与剪切速率 | I7: 常态 | J7: 1
A8: 水解工段 | B8: 结构关系 | C8: 物料流股 | D8: RB浓缩原料液 | E8: 具有属性 | F8: 工艺属性 | G8: RB进料温度 | H8: 底物RB原料液管道来料温度 | I8: 常态 | J8: 1
A9: 水解工段 | B9: 结构关系 | C9: 物料流股 | D9: RB浓缩原料液 | E9: 具有属性 | F9: 工艺属性 | G9: RB进料流量 | H9: 底物RB原料液瞬时进料流量 | I9: 常态 | J9: 1
A10: 水解工段 | B10: 结构关系 | C10: 物料流股 | D10: 硼酸缓冲液 | E10: 具有属性 | F10: 工艺属性 | G10: 硼酸溶液温度 | H10: 辅料硼酸缓冲液配制来料温度 | I10: 常态 | J10: 1
A11: 水解工段 | B11: 结构关系 | C11: 物料流股 | D11: 硼酸缓冲液 | E11: 具有属性 | F11: 工艺属性 | G11: 硼酸进料流量 | H11: 辅料硼酸缓冲液进料流量 | I11: 常态 | J11: 1
A12: 水解工段 | B12: 结构关系 | C12: 物料流股 | D12: 中和氨水 | E12: 具有属性 | F12: 工艺属性 | G12: 氨水加料流量 | H12: pH中和滴加氨水瞬时流量 | I12: 常态 | J12: 1
A13: 水解工段 | B13: 控制关系 | C13: 控制仪表 | D13: pH指示控制器(AIC) | E13: 控制 | F13: 执行机构 | G13: 氨水加料气动调节阀 | H13: pH控制器根据偏差实时调节氨水滴加阀开度 | I13: 闭环调节 | J13: 1
... A72: 跨工段协同 | B72: 质量关系 | C72: 质量指标 | D72: 废有机相6-APA夹带残效 | E72: 负向影响 | F72: 业务指标 | G72: 全厂批次最终提取收率 | H72: 萃取分离损失直接吞噬实际产出 | I72: 全局收率 | J72: 1
